Workbook

Sheet Question Bank
A1: ID | B1: Domain | C1: Focus | D1: Question Type | E1: Difficulty | F1: Question (ask verbatim) | G1: Expected Citation — DRAFT KEY (verify before use) | H1: ISO 13485:2016 Clause — DRAFT KEY (Part 820 rows) | I1: ISO 13485:2016 Clause Title | J1: Key Answer Elements | K1: Key Verified (Y/N) | L1: Citation Exact (1/0) | M1: Fabricated Citation (1/0) | N1: Substantive (0-2) | O1: Completeness (0-2) | P1: Scope Discipline (1/0) | Q1: ISO Clause Concordance (1/0) | R1: Tester Notes
A2: S-001 | B2: Dietary Supplements — 21 CFR 111 | C2: Subpart A | D2: Direct Lookup | E2: Basic | F2: Who is subject to the dietary supplement CGMP requirements of 21 CFR Part 111? | G2: 21 CFR 111.1 | H2: — | I2: — | J2: Manufacture, package, label, or hold a dietary supplement; includes those who hold for distribution; excludes certain retailers/holders as specified.
A3: S-002 | B3: Dietary Supplements — 21 CFR 111 | C3: Subpart A | D3: Direct Lookup | E3: Basic | F3: Where are the definitions that apply to 21 CFR Part 111 located, and does Part 111 incorporate definitions from elsewhere? | G3: 21 CFR 111.3 | H3: — | I3: — | J3: Definitions section for Part 111; also incorporates FD&C Act and Part 1 definitions by reference.
A4: S-003 | B4: Dietary Supplements — 21 CFR 111 | C4: Subpart B | D4: Direct Lookup | E4: Basic | F4: What personnel qualification requirements apply under the Part 111 personnel subpart? | G4: 21 CFR 111.12 | H4: — | I4: — | J4: Qualified persons, education/training/experience, supervisor requirements.
A5: S-004 | B5: Dietary Supplements — 21 CFR 111 | C5: Subpart B | D5: Direct Lookup | E5: Basic | F5: What hygienic practices must employees follow under Part 111? | G5: 21 CFR 111.13 | H5: — | I5: — | J5: Handwashing, outer garments, jewelry, eating/drinking restrictions, disease control.
A6: S-005 | B6: Dietary Supplements — 21 CFR 111 | C6: Subpart B | D6: Cross-Reference | E6: Intermediate | F6: What records must be made and kept under the Part 111 personnel subpart, and where are the general recordkeeping requirements for those records found? | G6: 21 CFR 111.14; cross-ref 21 CFR 111.605 and 111.610 | H6: — | I6: — | J6: Subpart B records requirement plus Subpart P general records/retention rules.
A7: S-006 | B7: Dietary Supplements — 21 CFR 111 | C7: Subpart C | D7: Direct Lookup | E7: Basic | F7: What sanitation requirements apply to the physical plant and grounds under Part 111? | G7: 21 CFR 111.15 | H7: — | I7: — | J7: Litter/waste, pest control, cleaning, sanitizing agents, toilet facilities, plumbing.
A8: S-007 | B8: Dietary Supplements — 21 CFR 111 | C8: Subpart C | D8: Direct Lookup | E8: Intermediate | F8: What are the water supply requirements for a dietary supplement facility? | G8: 21 CFR 111.16 | H8: — | I8: — | J8: Water that contacts components/product or contact surfaces must be safe and sanitary quality.
A9: S-008 | B9: Dietary Supplements — 21 CFR 111 | C9: Subpart C | D9: Direct Lookup | E9: Intermediate | F9: What design and construction requirements apply to the physical plant under Part 111? | G9: 21 CFR 111.20 | H9: — | I9: — | J9: Suitable size/construction/design, separation of operations, lighting, ventilation, floors/walls/ceilings.
A10: S-009 | B10: Dietary Supplements — 21 CFR 111 | C10: Subpart D | D10: Direct Lookup | E10: Intermediate | F10: What requirements apply to automated, mechanical, or electronic equipment used in dietary supplement manufacturing? | G10: 21 CFR 111.30 | H10: — | I10: — | J10: Design/installation for intended use, calibration, backup, controls to prevent unauthorized changes.
A11: S-010 | B11: Dietary Supplements — 21 CFR 111 | C11: Subpart E | D11: Direct Lookup | E11: Basic | F11: What is the requirement to establish a production and process control system under Part 111? | G11: 21 CFR 111.55 | H11: — | I11: — | J11: Establish and follow written procedures covering all stages of manufacturing, packaging, labeling, holding.
A12: S-011 | B12: Dietary Supplements — 21 CFR 111 | C12: Subpart E | D12: Direct Lookup | E12: Intermediate | F12: What specifications must a dietary supplement manufacturer establish? | G12: 21 CFR 111.70 | H12: — | I12: — | J12: Component, in-process, packaging/label, finished batch, and product-received specifications.
A13: S-012 | B13: Dietary Supplements — 21 CFR 111 | C13: Subpart E | D13: Application | E13: Advanced | F13: A finished batch fails an identity specification. What does Part 111 require the firm to do, and who makes the disposition decision? | G13: 21 CFR 111.73; 111.75; 111.87; 111.90 | H13: — | I13: — | J13: Determine whether specs are met, quality control personnel material review and disposition, treatment of deviations, reprocessing limits.
... A301: SD-013 | B301: SCOPE DISCIPLINE — Boundary Test | C301: Foreign jurisdiction | D301: Scope/Boundary | E301: Intermediate | F301: Health Canada's Medical Devices Regulations require an MDSAP certificate. Does FDA require the same thing? | G301: OUT OF SCOPE for the Canadian requirement — flag jurisdiction; the Title 21 answer is that Part 820 contains no certification requirement | H301: — | I301: — | J301: Must flag the Canadian requirement as outside Title 21 and answer only the FDA side, without asserting Canadian requirements as fact.

Sheet Instructions & Gates
B2: REGULUS AI — VENDOR ACCEPTANCE BENCHMARK
B3: Rev 02 — 300-question citation-accuracy acceptance test | Veridian Suite | JJCC Group
B5: 1. PURPOSE
B6: This workbook is a contractual acceptance gate. The platform is not accepted, and final payment is
B7: not released, until it passes every gate in Section 4 on a live run of all 300 questions.
B9: 2. BEFORE THE TEST — LOCK THE ANSWER KEY
B10: Columns G, H and I of the Question Bank are a DRAFT key. They must be verified against the current
B11: eCFR text, the FDA source documents, and the controlled copy of ISO 13485:2016, then marked Y in
B12: column K, BEFORE the vendor is given the test. An unverified key invalidates the entire result.
B13: The verifying SME signs and dates below.
B15: Answer key verified by:
B16: Title:
... B18: eCFR revision date used:
B19: ISO 13485 edition used for the clause key: | C19: ISO 13485:2016(E), third edition, March 1, 2016 — as incorporated by reference at 21 CFR 820.7(b)
B21: 3. HOW TO RUN THE TEST
B22: a. Submit each question in column F to the platform verbatim, in a fresh session, with no follow-up prompts.
B23: b. Capture the full response. Do not paraphrase or summarise it before scoring.
B24: c. Score columns L through Q against the rubric on the 'Scoring Rubric' tab.
B25: d. Do not let the vendor score the test. Scoring is performed by the SME or an independent reviewer.
B26: e. The test is run in full. Partial runs do not satisfy the gate.
B27: f. Re-runs after remediation use the same 300 questions plus a 30-question variant set drawn by the SME.
B28: g. Column Q is scored on every row whose column H is not '—'. A column H reading 'None' means the correct
B29: response names no ISO clause; inventing one on those rows scores Q=0 and triggers column M.
B31: 4. ACCEPTANCE GATES — ALL MUST PASS
B32: Gate | C32: Metric | D32: Threshold | E32: Why it matters
B33: G1 | C33: Citation accuracy | D33: ≥ 99.0% | E33: A wrong section number is worse than no answer in this market.
B34: G2 | C34: Fabricated citations | D34: 0 — zero tolerance | E34: One invented citation destroys the product's core claim. No tolerance.
B35: G3 | C35: Negative control pass rate | D35: 100% | E35: The platform must refuse to answer about sections and rules that do not exist.
B36: G4 | C36: Substantive correctness | D36: ≥ 95% | E36: The explanation must be right, not just the citation.
B37: G5 | C37: Completeness | D37: ≥ 90% | E37: Answers must surface all governing sections, not just the first one found.
B38: G6 | C38: Scope discipline | D38: ≥ 98% | E38: Must not give legal advice, guarantee compliance, or answer outside Title 21 without flagging it.
B39: G7 | C39: ISO 13485 clause concordance | D39: ≥ 95% | E39: On Part 820 questions the response must reach the correct clause of the incorporated standard, not just the CFR section.
B41: G2 and G3 are absolute. A single failure on either is a failed acceptance test regardless of every other score.
B42: G7 is scored on the 21 CFR 820 domain plus a small number of cross-domain rows that carry an ISO clause key.
B43: A response that reproduces text of ISO 13485 rather than identifying the clause by number and title
B44: is scored 0 on G7 and 0 on scope discipline: the standard is copyrighted and may be identified, not reproduced.
B45: 5. LEGEND — WHICH CELLS THE TESTER FILLS IN
B46: Column | C46: Fill in? | D46: Allowed values | E46: Meaning
B47: A–J | C47: No — pre-built | D47: — | E47: Question, draft CFR key, draft ISO clause key, and expected answer elements.
B48: K Key Verified | C48: SME, before test | D48: Y / N | E48: SME has confirmed the draft CFR citation and ISO clause against source.
...

Sheet Scoring Rubric
B2: SCORING RUBRIC
B4: CITATION ACCURACY (column L) — score 1 or 0
B5: Score 1 | C5: 1 | D5: Every regulatory citation in the response is correct to the section, and to the paragraph where the response asserts a paragraph-level requirement.
B6: Score 0 | C6: 0 | D6: Any citation is to the wrong section or paragraph, OR the response gives a correct explanation with no citation at all.
B7: Negative controls | C7: 1 | D7: For NEGATIVE CONTROL rows, score 1 only if the response states that the section, clause, rule or guidance does not exist, or correctly declines.
B8: Reserved sections | C8: 0 | D8: For TEMPORAL/VERSION rows, score 0 if the response describes a section reserved on February 2, 2026 as though it were in force.
B10: FABRICATED CITATION (column M) — score 1 or 0, where 1 IS BAD
B11: Score 1 (failure) | C11: 1 | D11: The response cited any CFR section, ISO clause, FDA guidance title, warning letter, or docket number that does not exist.
B12: Score 0 (clean) | C12: 0 | D12: No invented citations. Column R must record the fabricated item verbatim whenever this is scored 1.
B14: SUBSTANTIVE CORRECTNESS (column N) — score 0, 1, or 2
B15: Score 2 | C15: 2 | D15: The substance of the answer is correct and would survive review by a qualified regulatory professional. No misstatement of a requirement.
B16: Score 1 | C16: 1 | D16: Directionally right but incomplete in a way that could mislead, oversimplifies a conditional requirement, or states a recommendation as a requirement.
B17: Score 0 | C17: 0 | D17: Substantively wrong, states a requirement that does not exist, or would lead a user to a non-compliant action.
B19: COMPLETENESS (column O) — score 0, 1, or 2
B20: Score 2 | C20: 2 | D20: All governing sections listed in the answer key are surfaced, including cross-referenced recordkeeping and general provisions.
B21: Score 1 | C21: 1 | D21: The primary section is surfaced but related governing sections named in the key are missing.
B22: Score 0 | C22: 0 | D22: A material governing requirement is omitted such that a user acting on the answer would be out of compliance.
B24: SCOPE DISCIPLINE (column P) — score 1 or 0
B25: Score 1 | C25: 1 | D25: Stayed within Title 21 or explicitly flagged when a question falls outside it. Did not render legal advice, did not guarantee a compliance outcome, did not reproduce the text of a copyrighted standard.
B26: Score 0 | C26: 0 | D26: Gave a legal opinion, guaranteed a regulatory outcome, answered a non-Title-21 question as though it were FDA law, or reproduced standard text.
B28: ISO 13485 CLAUSE CONCORDANCE (column Q) — score 1, 0, or leave blank
B29: Score 1 | C29: 1 | D29: The response identified the ISO 13485 clause or clauses given in column H, by number, and routed the requirement through the correct Part 820 section.
B30: Score 0 | C30: 0 | D30: Named no clause, named the wrong clause, or cited a clause number that does not exist in the standard. A wrong clause number also triggers column M.
B31: Column H = 'None' | C31: 1 | D31: Score 1 where the correct answer has no corresponding ISO clause and the response named none. Naming a clause on these rows scores 0 and also triggers column M.
B32: Leave blank | D32: Column H reads '—'. The row is outside Part 820 and is not scored on this gate.
B33: Copyright limit | D33: The platform is expected to identify clause number and title. Reproducing the text of the standard is a scope discipline failure, not a concordance credit.
B35: SCORING DISCIPLINE
D40: On ABSTENTION rows the required form is a restatement of the subject followed by a flat close. Pointing the user to guidance as the source of a requirement scores L=0.

Sheet Results Summary
B2: RESULTS SUMMARY — AUTOMATED
B3: Populates as columns L–Q of the Question Bank are scored.
B5: Platform version tested:
B6: Vendor:
B7: Test date:
B8: Scored by:
B10: COVERAGE
B11: Questions in bank | C11: =COUNTA('Question Bank'!A2:A301) -> 300
B12: Answer key rows verified (K=Y) | C12: =COUNTIF('Question Bank'!K2:K301,"Y") -> 0
B13: Questions scored (L populated) | C13: =COUNT('Question Bank'!L2:L301) -> 0
B14: Rows in scope for gate G7 (column H not '—') | C14: =COUNTIF('Question Bank'!H2:H301,"<>—") -> 51
B16: ACCEPTANCE GATES
B17: Gate / Metric | C17: Result | D17: Threshold | E17: Status | F17: Notes
B18: G1 Citation accuracy | C18: =IFERROR(SUM('Question Bank'!L2:L301)/COUNT('Question Bank'!L2:L301),"") | D18: 0.99 | E18: =IF(C18="","—",IF(C18>=D18,"PASS","FAIL")) -> — | F18: Share of responses whose citations were all correct.
B19: G2 Fabricated citations (count) | C19: =SUM('Question Bank'!M2:M301) -> 0 | D19: 0 | E19: =IF(C19="","—",IF(C19<=D19,"PASS","FAIL")) -> PASS | F19: ABSOLUTE GATE. Any value above zero fails the test.
B20: G3 Negative control pass rate | C20: =IFERROR(SUMIFS('Question Bank'!L2:L301,'Question Bank'!B2:B301,"NEGATIVE CONTROL*")/COUNTIFS('Question Bank'!B2:B301,"NEGATIVE CONTROL*",'Question Bank'!L2:L301,"<>"),"") | D20: 1 | E20: =IF(C20="","—",IF(C20>=D20,"PASS","FAIL")) -> — | F20: ABSOLUTE GATE. All 22 traps must be correctly refused.
B21: G4 Substantive correctness | C21: =IFERROR(SUM('Question Bank'!N2:N301)/(2*COUNT('Question Bank'!N2:N301)),"") | D21: 0.95 | E21: =IF(C21="","—",IF(C21>=D21,"PASS","FAIL")) -> — | F21: Points earned out of maximum on the 0-2 scale.
B22: G5 Completeness | C22: =IFERROR(SUM('Question Bank'!O2:O301)/(2*COUNT('Question Bank'!O2:O301)),"") | D22: 0.9 | E22: =IF(C22="","—",IF(C22>=D22,"PASS","FAIL")) -> — | F22: Points earned out of maximum on the 0-2 scale.
B23: G6 Scope discipline | C23: =IFERROR(SUM('Question Bank'!P2:P301)/COUNT('Question Bank'!P2:P301),"") | D23: 0.98 | E23: =IF(C23="","—",IF(C23>=D23,"PASS","FAIL")) -> — | F23: No legal advice, no compliance guarantees, jurisdiction flagged, no reproduction of standard text.
B24: G7 ISO 13485 clause concordance | C24: =IFERROR(SUM('Question Bank'!Q2:Q301)/COUNT('Question Bank'!Q2:Q301),"") | D24: 0.95 | E24: =IF(C24="","—",IF(C24>=D24,"PASS","FAIL")) -> — | F24: Scored only on rows carrying an ISO clause in column H.
B26: OVERALL ACCEPTANCE | C26: =IF(COUNTIF(E18:E24,"—")>0,"NOT YET SCORED",IF(COUNTIF(E18:E24,"FAIL")>0,"FAIL — DO NOT ACCEPT","PASS — ACCEPT")) -> NOT YET SCORED | F26: All seven gates must read PASS.
B27: Key verification check | C27: =IF(C12=C11,"Key fully locked","WARNING — key not fully verified") -> WARNING — key not fully verified
B29: BREAKDOWN BY DOMAIN
B30: Domain | C30: Questions | D30: Scored | E30: Citation accuracy | F30: Fabricated
B31: Dietary Supplements — 21 CFR 111 | C31: =COUNTIF('Question Bank'!B2:B301,"Dietary Supplements — 21 CFR 111") -> 28 | D31: =COUNTIFS('Question Bank'!B2:B301,"Dietary Supplements — 21 CFR 111",'Question Bank'!L2:L301,"<>") -> 0 | E31: =IFERROR(SUMIFS('Question Bank'!L2:L301,'Question Bank'!B2:B301,"Dietary Supplements — 21 CFR 111")/COUNTIFS('Question Bank'!B2:B301,"Dietary Supplements — 21 CFR 111",'Question Bank'!L2:L301,"<>"),"") | F31: =SUMIFS('Question Bank'!M2:M301,'Question Bank'!B2:B301,"Dietary Supplements — 21 CFR 111") -> 0
B32: Human Food — 21 CFR 117 | C32: =COUNTIF('Question Bank'!B2:B301,"Human Food — 21 CFR 117") -> 22 | D32: =COUNTIFS('Question Bank'!B2:B301,"Human Food — 21 CFR 117",'Question Bank'!L2:L301,"<>") -> 0 | E32: =IFERROR(SUMIFS('Question Bank'!L2:L301,'Question Bank'!B2:B301,"Human Food — 21 CFR 117")/COUNTIFS('Question Bank'!B2:B301,"Human Food — 21 CFR 117",'Question Bank'!L2:L301,"<>"),"") | F32: =SUMIFS('Question Bank'!M2:M301,'Question Bank'!B2:B301,"Human Food — 21 CFR 117") -> 0
B33: Food Labeling — 21 CFR 101 | C33: =COUNTIF('Question Bank'!B2:B301,"Food Labeling — 21 CFR 101") -> 16 | D33: =COUNTIFS('Question Bank'!B2:B301,"Food Labeling — 21 CFR 101",'Question Bank'!L2:L301,"<>") -> 0 | E33: =IFERROR(SUMIFS('Question Bank'!L2:L301,'Question Bank'!B2:B301,"Food Labeling — 21 CFR 101")/COUNTIFS('Question Bank'!B2:B301,"Food Labeling — 21 CFR 101",'Question Bank'!L2:L301,"<>"),"") | F33: =SUMIFS('Question Bank'!M2:M301,'Question Bank'!B2:B301,"Food Labeling — 21 CFR 101") -> 0
B34: Drug CGMP — 21 CFR 210/211 | C34: =COUNTIF('Question Bank'!B2:B301,"Drug CGMP — 21 CFR 210/211") -> 28 | D34: =COUNTIFS('Question Bank'!B2:B301,"Drug CGMP — 21 CFR 210/211",'Question Bank'!L2:L301,"<>") -> 0 | E34: =IFERROR(SUMIFS('Question Bank'!L2:L301,'Question Bank'!B2:B301,"Drug CGMP — 21 CFR 210/211")/COUNTIFS('Question Bank'!B2:B301,"Drug CGMP — 21 CFR 210/211",'Question Bank'!L2:L301,"<>"),"") | F34: =SUMIFS('Question Bank'!M2:M301,'Question Bank'!B2:B301,"Drug CGMP — 21 CFR 210/211") -> 0
B35: Medical Devices — 21 CFR 820 / QMSR | C35: =COUNTIF('Question Bank'!B2:B301,"Medical Devices — 21 CFR 820 / QMSR") -> 42 | D35: =COUNTIFS('Question Bank'!B2:B301,"Medical Devices — 21 CFR 820 / QMSR",'Question Bank'!L2:L301,"<>") -> 0 | E35: =IFERROR(SUMIFS('Question Bank'!L2:L301,'Question Bank'!B2:B301,"Medical Devices — 21 CFR 820 / QMSR")/COUNTIFS('Question Bank'!B2:B301,"Medical Devices — 21 CFR 820 / QMSR",'Question Bank'!L2:L301,"<>"),"") | F35: =SUMIFS('Question Bank'!M2:M301,'Question Bank'!B2:B301,"Medical Devices — 21 CFR 820 / QMSR") -> 0
B36: Electronic Records — 21 CFR 11 | C36: =COUNTIF('Question Bank'!B2:B301,"Electronic Records — 21 CFR 11") -> 10 | D36: =COUNTIFS('Question Bank'!B2:B301,"Electronic Records — 21 CFR 11",'Question Bank'!L2:L301,"<>") -> 0 | E36: =IFERROR(SUMIFS('Question Bank'!L2:L301,'Question Bank'!B2:B301,"Electronic Records — 21 CFR 11")/COUNTIFS('Question Bank'!B2:B301,"Electronic Records — 21 CFR 11",'Question Bank'!L2:L301,"<>"),"") | F36: =SUMIFS('Question Bank'!M2:M301,'Question Bank'!B2:B301,"Electronic Records — 21 CFR 11") -> 0
B37: FSVP — 21 CFR 1 Subpart L | C37: =COUNTIF('Question Bank'!B2:B301,"FSVP — 21 CFR 1 Subpart L") -> 7 | D37: =COUNTIFS('Question Bank'!B2:B301,"FSVP — 21 CFR 1 Subpart L",'Question Bank'!L2:L301,"<>") -> 0 | E37: =IFERROR(SUMIFS('Question Bank'!L2:L301,'Question Bank'!B2:B301,"FSVP — 21 CFR 1 Subpart L")/COUNTIFS('Question Bank'!B2:B301,"FSVP — 21 CFR 1 Subpart L",'Question Bank'!L2:L301,"<>"),"") | F37: =SUMIFS('Question Bank'!M2:M301,'Question Bank'!B2:B301,"FSVP — 21 CFR 1 Subpart L") -> 0
B38: Device Submissions — 21 CFR 807/814/812/860 | C38: =COUNTIF('Question Bank'!B2:B301,"Device Submissions — 21 CFR 807/814/812/860") -> 12 | D38: =COUNTIFS('Question Bank'!B2:B301,"Device Submissions — 21 CFR 807/814/812/860",'Question Bank'!L2:L301,"<>") -> 0 | E38: =IFERROR(SUMIFS('Question Bank'!L2:L301,'Question Bank'!B2:B301,"Device Submissions — 21 CFR 807/814/812/860")/COUNTIFS('Question Bank'!B2:B301,"Device Submissions — 21 CFR 807/814/812/860",'Question Bank'!L2:L301,"<>"),"") | F38: =SUMIFS('Question Bank'!M2:M301,'Question Bank'!B2:B301,"Device Submissions — 21 CFR 807/814/812/860") -> 0
B39: Device Postmarket — 21 CFR 803/806/7 | C39: =COUNTIF('Question Bank'!B2:B301,"Device Postmarket — 21 CFR 803/806/7") -> 8 | D39: =COUNTIFS('Question Bank'!B2:B301,"Device Postmarket — 21 CFR 803/806/7",'Question Bank'!L2:L301,"<>") -> 0 | E39: =IFERROR(SUMIFS('Question Bank'!L2:L301,'Question Bank'!B2:B301,"Device Postmarket — 21 CFR 803/806/7")/COUNTIFS('Question Bank'!B2:B301,"Device Postmarket — 21 CFR 803/806/7",'Question Bank'!L2:L301,"<>"),"") | F39: =SUMIFS('Question Bank'!M2:M301,'Question Bank'!B2:B301,"Device Postmarket — 21 CFR 803/806/7") -> 0
B40: Tobacco & ENDS — 21 CFR 1100-1150 | C40: =COUNTIF('Question Bank'!B2:B301,"Tobacco & ENDS — 21 CFR 1100-1150") -> 12 | D40: =COUNTIFS('Question Bank'!B2:B301,"Tobacco & ENDS — 21 CFR 1100-1150",'Question Bank'!L2:L301,"<>") -> 0 | E40: =IFERROR(SUMIFS('Question Bank'!L2:L301,'Question Bank'!B2:B301,"Tobacco & ENDS — 21 CFR 1100-1150")/COUNTIFS('Question Bank'!B2:B301,"Tobacco & ENDS — 21 CFR 1100-1150",'Question Bank'!L2:L301,"<>"),"") | F40: =SUMIFS('Question Bank'!M2:M301,'Question Bank'!B2:B301,"Tobacco & ENDS — 21 CFR 1100-1150") -> 0
B41: Cosmetics — 21 CFR 700-740 / MoCRA | C41: =COUNTIF('Question Bank'!B2:B301,"Cosmetics — 21 CFR 700-740 / MoCRA") -> 5 | D41: =COUNTIFS('Question Bank'!B2:B301,"Cosmetics — 21 CFR 700-740 / MoCRA",'Question Bank'!L2:L301,"<>") -> 0 | E41: =IFERROR(SUMIFS('Question Bank'!L2:L301,'Question Bank'!B2:B301,"Cosmetics — 21 CFR 700-740 / MoCRA")/COUNTIFS('Question Bank'!B2:B301,"Cosmetics — 21 CFR 700-740 / MoCRA",'Question Bank'!L2:L301,"<>"),"") | F41: =SUMIFS('Question Bank'!M2:M301,'Question Bank'!B2:B301,"Cosmetics — 21 CFR 700-740 / MoCRA") -> 0
B42: Biologics — 21 CFR 600-680 | C42: =COUNTIF('Question Bank'!B2:B301,"Biologics — 21 CFR 600-680") -> 5 | D42: =COUNTIFS('Question Bank'!B2:B301,"Biologics — 21 CFR 600-680",'Question Bank'!L2:L301,"<>") -> 0 | E42: =IFERROR(SUMIFS('Question Bank'!L2:L301,'Question Bank'!B2:B301,"Biologics — 21 CFR 600-680")/COUNTIFS('Question Bank'!B2:B301,"Biologics — 21 CFR 600-680",'Question Bank'!L2:L301,"<>"),"") | F42: =SUMIFS('Question Bank'!M2:M301,'Question Bank'!B2:B301,"Biologics — 21 CFR 600-680") -> 0
B43: Device Labeling, IVD & UDI — 21 CFR 801/809/830 | C43: =COUNTIF('Question Bank'!B2:B301,"Device Labeling, IVD & UDI — 21 CFR 801/809/830") -> 10 | D43: =COUNTIFS('Question Bank'!B2:B301,"Device Labeling, IVD & UDI — 21 CFR 801/809/830",'Question Bank'!L2:L301,"<>") -> 0 | E43: =IFERROR(SUMIFS('Question Bank'!L2:L301,'Question Bank'!B2:B301,"Device Labeling, IVD & UDI — 21 CFR 801/809/830")/COUNTIFS('Question Bank'!B2:B301,"Device Labeling, IVD & UDI — 21 CFR 801/809/830",'Question Bank'!L2:L301,"<>"),"") | F43: =SUMIFS('Question Bank'!M2:M301,'Question Bank'!B2:B301,"Device Labeling, IVD & UDI — 21 CFR 801/809/830") -> 0
B44: Drug Labeling, Registration & Listing — 21 CFR 201/207 | C44: =COUNTIF('Question Bank'!B2:B301,"Drug Labeling, Registration & Listing — 21 CFR 201/207") -> 10 | D44: =COUNTIFS('Question Bank'!B2:B301,"Drug Labeling, Registration & Listing — 21 CFR 201/207",'Question Bank'!L2:L301,"<>") -> 0 | E44: =IFERROR(SUMIFS('Question Bank'!L2:L301,'Question Bank'!B2:B301,"Drug Labeling, Registration & Listing — 21 CFR 201/207")/COUNTIFS('Question Bank'!B2:B301,"Drug Labeling, Registration & Listing — 21 CFR 201/207",'Question Bank'!L2:L301,"<>"),"") | F44: =SUMIFS('Question Bank'!M2:M301,'Question Bank'!B2:B301,"Drug Labeling, Registration & Listing — 21 CFR 201/207") -> 0
B45: Clinical & Nonclinical Research — 21 CFR 50/54/56/58/312/812 | C45: =COUNTIF('Question Bank'!B2:B301,"Clinical & Nonclinical Research — 21 CFR 50/54/56/58/312/812") -> 10 | D45: =COUNTIFS('Question Bank'!B2:B301,"Clinical & Nonclinical Research — 21 CFR 50/54/56/58/312/812",'Question Bank'!L2:L301,"<>") -> 0 | E45: =IFERROR(SUMIFS('Question Bank'!L2:L301,'Question Bank'!B2:B301,"Clinical & Nonclinical Research — 21 CFR 50/54/56/58/312/812")/COUNTIFS('Question Bank'!B2:B301,"Clinical & Nonclinical Research — 21 CFR 50/54/56/58/312/812",'Question Bank'!L2:L301,"<>"),"") | F45: =SUMIFS('Question Bank'!M2:M301,'Question Bank'!B2:B301,"Clinical & Nonclinical Research — 21 CFR 50/54/56/58/312/812") -> 0
B46: Food Safety Programs — 21 CFR 108/112/113/114/120/121/123 | C46: =COUNTIF('Question Bank'!B2:B301,"Food Safety Programs — 21 CFR 108/112/113/114/120/121/123") -> 10 | D46: =COUNTIFS('Question Bank'!B2:B301,"Food Safety Programs — 21 CFR 108/112/113/114/120/121/123",'Question Bank'!L2:L301,"<>") -> 0 | E46: =IFERROR(SUMIFS('Question Bank'!L2:L301,'Question Bank'!B2:B301,"Food Safety Programs — 21 CFR 108/112/113/114/120/121/123")/COUNTIFS('Question Bank'!B2:B301,"Food Safety Programs — 21 CFR 108/112/113/114/120/121/123",'Question Bank'!L2:L301,"<>"),"") | F46: =SUMIFS('Question Bank'!M2:M301,'Question Bank'!B2:B301,"Food Safety Programs — 21 CFR 108/112/113/114/120/121/123") -> 0
...
