Workbook

Sheet Summary
A1: Regulus AI Acceptance Benchmark REV02 (300Q): Test Results
A2: Every question carries an explicit result in Detailed Results, scored question by question against the workbook's own rubric (columns L-Q) and against the regulation text in the read-only eCFR snapshot - not against the draft key alone. Where the draft key is itself wrong, the answer was judged against the regulation and the discrepancy is recorded in Evaluator Notes. The key remains unverified by an SME (0 of 300 rows marked Y in column K), so these results are an independent reviewer's scoring, not a signed-off contractual acceptance result: an SME should countersign before the gates are treated as final.
A3: Metric | B3: Value
A4: Total questions | B4: 300
A5: Questions successfully tested | B5: =COUNTIF('Detailed Results'!$L$2:$L$301,"OK")
A6: Questions failed to execute (ERROR) | B6: =COUNTIF('Detailed Results'!$M$2:$M$301,"ERROR")
A7: Questions not tested | B7: =COUNTIF('Detailed Results'!$M$2:$M$301,"NOT TESTED")
A8: Questions passed | B8: =COUNTIF('Detailed Results'!$M$2:$M$301,"PASS")
A9: Questions failed | B9: =COUNTIF('Detailed Results'!$M$2:$M$301,"FAIL")
A10: Questions requiring SME review | B10: =COUNTIF('Detailed Results'!$M$2:$M$301,"REQUIRES SME REVIEW")
A11: Pass rate % (PASS / (PASS+FAIL)) | B11: =IF(B8+B9=0,"Not determinable (no rows scored)",B8/(B8+B9))
A12: Fail rate % (FAIL / (PASS+FAIL)) | B12: =IF(B8+B9=0,"Not determinable (no rows scored)",B9/(B8+B9))
A13: Execution error rate % (ERROR / total) | B13: =B6/B4
A14: Execution success rate % (tested / total) | B14: =B5/B4
A15: SME review rate % (REQUIRES SME REVIEW / total) | B15: =B10/B4
A16: Average response time (s), executed rows | B16: =AVERAGEIF('Detailed Results'!$L$2:$L$301,"OK",'Detailed Results'!$K$2:$K$301)
A17: Median response time (s), executed rows (computed in Python from column K; no conditional-median formula) | B17: 14.79
A18: Rows flagged borderline for an SME second look | B18: =COUNTIF('Detailed Results'!$Q$2:$Q$301,"Y")
A19: Answers with partial credit (see Partially Correct sheet) | B19: =COUNTIFS('Detailed Results'!$M$2:$M$301,"FAIL",'Detailed Results'!$T$2:$T$301,">=1")+COUNTIFS('Detailed Results'!$M$2:$M$301,"FAIL",'Detailed Results'!$T$2:$T$301,"0",'Detailed Results'!$U$2:$U$301,">=1")
A20: of those, substance fully correct, blocked on another dimension | B20: =COUNTIFS('Detailed Results'!$M$2:$M$301,"FAIL",'Detailed Results'!$T$2:$T$301,2)
A21: of those, directionally right but materially incomplete | B21: =COUNTIFS('Detailed Results'!$M$2:$M$301,"FAIL",'Detailed Results'!$T$2:$T$301,1)
A22: Answers with no partial credit (substance and completeness both 0) | B22: =COUNTIFS('Detailed Results'!$M$2:$M$301,"FAIL",'Detailed Results'!$T$2:$T$301,0,'Detailed Results'!$U$2:$U$301,0)
A24: Test date/time (UTC) | B24: 2026-10-01T08:40:00+00:00 to 2026-10-01T11:41:13+00:00
A25: Model/checkpoint | B25: Qwen/Qwen3-0.6B @ c1899de289a04d12100db370d81485cdf75e47ca (base model, no adapter; weights sha256 f47f71177f32bcd101b7573ec9171e6a57f4f4d31148d38e382306f42996874b)
A26: Git commit/version | B26: 800af071e1067db4b4f9d31dd5c0309f7fb2589d (working tree had uncommitted files: the test scripts)
A27: Test environment | B27: macOS-26.1-arm64-arm-64bit; device cpu, dtype float32; Apple M2, 8 GB; read-only PostgreSQL eCFR snapshot
A28: Benchmark file / sha256 before → after | B28: Regulus_AI_Acceptance_Benchmark_REV02_300Q.xlsx / c009d5f9c649822097b02a6c6aba415715fb0929914ef452acb03c8c3ac4a110 → c009d5f9c649822097b02a6c6aba415715fb0929914ef452acb03c8c3ac4a110 (now c009d5f9c649822097b02a6c6aba415715fb0929914ef452acb03c8c3ac4a110)
A30: ACCEPTANCE GATES (computed from rubric columns R-W of Detailed Results) | B30: Scored by an independent reviewer against the regulation text; the answer key itself remains unverified, so an SME must countersign before these are treated as final.
A31: Gate / metric | B31: Result | C31: Threshold | D31: Status | E31: Scored on
A32: G1 Citation accuracy | B32: =SUM('Detailed Results'!$R$2:$R$301)/COUNT('Detailed Results'!$R$2:$R$301) | C32: 99% | D32: =IF(B32>=0.99,"PASS","FAIL") | E32: every scored row, rubric L
A33: G2 Fabricated citations (count) | B33: =SUM('Detailed Results'!$S$2:$S$301) | C33: =0 | D33: =IF(B33<=0,"PASS","FAIL") | E33: every scored row, rubric M
A34: G3 Negative control pass rate | B34: =SUMIFS('Detailed Results'!$R$2:$R$301,'Detailed Results'!$C$2:$C$301,"Negative Control")/COUNTIFS('Detailed Results'!$C$2:$C$301,"Negative Control") | C34: 100% | D34: =IF(B34=1.0,"PASS","FAIL") | E34: the 22 Negative Control rows, rubric L
A35: G4 Substantive correctness | B35: =SUM('Detailed Results'!$T$2:$T$301)/(2*COUNT('Detailed Results'!$T$2:$T$301)) | C35: 95% | D35: =IF(B35>=0.95,"PASS","FAIL") | E35: points out of maximum, rubric N
A36: G5 Completeness | B36: =SUM('Detailed Results'!$U$2:$U$301)/(2*COUNT('Detailed Results'!$U$2:$U$301)) | C36: 90% | D36: =IF(B36>=0.9,"PASS","FAIL") | E36: points out of maximum, rubric O
A37: G6 Scope discipline | B37: =SUM('Detailed Results'!$V$2:$V$301)/COUNT('Detailed Results'!$V$2:$V$301) | C37: 98% | D37: =IF(B37>=0.98,"PASS","FAIL") | E37: every scored row, rubric P
A38: G7 ISO 13485 clause concordance | B38: =SUM('Detailed Results'!$W$2:$W$301)/COUNT('Detailed Results'!$W$2:$W$301) | C38: 95% | D38: =IF(B38>=0.95,"PASS","FAIL") | E38: rows carrying an ISO clause key, rubric Q
A39: OVERALL ACCEPTANCE (all seven gates must read PASS) | B39: =IF(COUNTIF(D32:D38,"FAIL")=0,"PASS","FAIL")
A40: Answer key verification (benchmark column K) | B40: 0 of 300 rows marked Y - WARNING, key not SME-verified
A42: Breakdown by category (Domain, col B)
A43: Category | B43: Total | C43: Tested | D43: Passed | E43: Failed | F43: Errors | G43: SME review | H43: Flagged (indicator)
...

Sheet Detailed Results
A1: Question ID | B1: Category (Domain) | C1: Question Type | D1: Difficulty | E1: Question (verbatim, col F) | F1: Expected Answer / Reference (col J, DRAFT) | G1: Model Answer (as shown to user) | H1: Citation Expected (col G/H, DRAFT) | I1: Citation Provided | J1: Citation vs Draft Key (indicator) | K1: Response Time (s) | L1: Execution Status | M1: Result | N1: Error | O1: Scoring Notes | P1: Evaluator Notes (verification + machine checks) | Q1: Borderline - SME second look | R1: L Citation Exact (1/0) | S1: M Fabricated Citation (1=fail) | T1: N Substantive (0-2) | U1: O Completeness (0-2) | V1: P Scope Discipline (1/0) | W1: Q ISO Clause (1/0/blank) | X1: Answerability State | Y1: Final Validation | Z1: Repair Applied | AA1: Evidence Retrieved | AB1: ISO Clauses Named | AC1: Raw Model Output (before validation/repair) | AD1: Key Verified (col K) | AE1: Benchmark Row
A2: S-001 | B2: Dietary Supplements — 21 CFR 111 | C2: Direct Lookup | D2: Basic | E2: Who is subject to the dietary supplement CGMP requirements of 21 CFR Part 111? | F2: [DRAFT KEY - NOT SME-VERIFIED] Manufacture, package, label, or hold a dietary supplement; includes those who hold for distribution; excludes certain retailers/holders as specified. | G2: The generated answer could not be validated against the retrieved regulatory evidence, so it is not shown. The retrieved sources were not verified to answer the question as asked, so their text is not quoted as an answer. Sources consulted: 21 CFR 111.103, 21 CFR 111.105, 21 CFR 111.10(a), 21 CFR 111.110, 21 CFR 111.113(a) and 16 more. | H2: 21 CFR 111.1 | I2: none (answer withheld) | J2: no CFR citation | K2: 28.15 | L2: OK | M2: FAIL | O2: No answer delivered: the pipeline withheld a degenerate, looping draft. 111.1 (who is subject) is never stated and nothing is cited. | P2: Draft key 111.1 verified correct against the snapshot. Raw output repeated quality-control sentences unrelated to the question. || MACHINE CHECKS: indicator: citation vs draft key: no CFR citation | indicator: answer withheld by validation (likely incomplete / no substantive answer) | pipeline validator codes on raw output: degenerate_output, truncated, low_overlap_with_cited_source, repeated_statement | Q2: N | R2: 0 | S2: 0 | T2: 0 | U2: 0 | V2: 1 | X2: ANSWERABLE | Y2: unsupported | Z2: unvalidated_answer_withheld | AA2: 21 CFR 111.103; 21 CFR 111.105; 21 CFR 111.10(a); 21 CFR 111.110; 21 CFR 111.113(a); 21 CFR 111.117; 21 CFR 111.120; 21 CFR 111.123(a); 21 CFR 111.127; 21 CFR 111.12(a); 21 CFR 111.130; 21 CFR 111.135; 21 CFR 111.13(a); 21 CFR 111.140(a); 21 CFR 111.14(a); 21 CFR 111.153; 21 CFR 111.155(a); 21 CFR 111.15(a); 21 CFR 111.160(a); 21 CFR 111.165(a); 21 CFR 111.16 | AC2: Who is subject to the dietary supplement CGMP requirements of 21 CFR Part 111? [1] Quality control personnel must ensure that your manufacturing, packaging, labeling, and holding operations ensure the quality of the dietary supplement and that the dietary supplement is packaged and labeled as specified in the master manufacturing record. [1] Quality control personnel must conduct a material review and make a disposition decision if [1] Quality control personnel must ensure that your manufacturing, packaging, labeling, and holding operations ensure the quality of the dietary supplement and that the dietary supplement is packaged and labeled as specified in the master manufacturing record. [1] Quality control personnel must ensure that your manufacturing, packaging, labeling, and holding operations ensure the quality of the dietary supplement and that the dietary supplement is packaged and labeled as specified in the master manufacturing record. [1] Quality control personnel must ensure that your manufacturing, packaging, labeling, and holding operations ensure the quality of the dietary supplement and that the dietary supplement is packaged and labeled as specified in the master manufacturing record. [1] Quality control personnel must ensure that your manufacturing, packaging, | AD2: unmarked | AE2: 2
A3: S-002 | B3: Dietary Supplements — 21 CFR 111 | C3: Direct Lookup | D3: Basic | E3: Where are the definitions that apply to 21 CFR Part 111 located, and does Part 111 incorporate definitions from elsewhere? | F3: [DRAFT KEY - NOT SME-VERIFIED] Definitions section for Part 111; also incorporates FD&C Act and Part 1 definitions by reference. | G3: 21 CFR Part 111 requires written procedures for quality control operations, including material review and disposition decisions, equipment, instruments, and controls, components, packaging, and labels, master manufacturing records, batch production records, and packaging and labeling operations, personnel qualification requirements, and returned dietary supplements. The requirements under this subpart include: - Written procedures for quality control operations, as outlined in 21 CFR 111.103, 111.105, 111.10(a), 111.110, 111.113(a), 111.117, 111.120, 111.123(a), 111.127, 111.12(a), 111.130, 111.135, 111.13(a), and 111.140(a). - Personnel qualification requirements, as outlined in 21 CFR 111.140(a) and 111.14(a). - Records required under this subpart, including master manufacturing records, batch production records, and packaging and labeling operations, as outlined in 21 CFR 111.14(a). - Requirements for components, packaging, and labels before use, as outlined in 21 CFR 111.127. - Requirements for returned dietary supplements, as outlined in 21 CFR 111.135. - Requirements for product complaints, as outlined in 21 CFR 111.13(a). - Requirements for supervision of quality control operations, as outlined in 21 CFR 111.130. - Requirements for sanitation and ground maintenance, as outlined in 21 CFR 111.15(a). - Requirements for packaging and labels received, as outlined in 21 CFR 111.160(a). - Requirements for contamination and deterioration checks, as outlined in 21 CFR 111.17. 21 CFR 111.103 (eCFR, binding, verbatim): You must establish and follow written procedures for the responsibilities of the quality control operations, including written procedures for conducting a material review and making a disposition decision, and for approving or rejecting any reprocessing [1]. 21 CFR 111.135 (eCFR, binding, verbatim): Quality control operations for product complaints must include reviewing and approving decisions about whether to investigate a product complaint and reviewing and approving the findings and followup action of any investigation performed [12]. 21 CFR 111.153 (eCFR, binding, verbatim): You must establish and follow written procedures for fulfilling the requirements of this subpart G [16]. 21 CFR 111.155(a) (eCFR, binding, verbatim): (a) You must visually examine each immediate container or grouping of immediate containers in a shipment that you receive for appropriate content label, container damage, or broken seals to determine whether the container condition may have resulted in contamination or deterioration of the components; [17]. 21 CFR 111.165(a) (eCFR, binding, verbatim): (a) You must visually examine each immediate container or grouping of immediate containers in a shipment of product that you receive for packaging or labeling as a dietary supplement (and for distribution rather than for return to the supplier) for appropriate content label, container damage, or broken seals to determine whether the container condition may have resulted in contamination or deterioration of the received product [20]. 21 CFR 111.16 (eCFR, binding, verbatim): You must establish and follow written procedures for cleaning the physical plant and for pest control [21]. | H3: 21 CFR 111.3 | I3: 21 CFR Part 111, 21 CFR 111.103, 111.105, 111.10(a), 111.110, 111.113(a), 111.117, 111.120, 111.123(a), 111.127, 111.12(a), 111.130, 111.135, 111.13(a), 111.140(a), 111.14(a), 21 CFR 111.15(a), 21 CFR 111.160(a), 21 CFR 111.17, 21 CFR 111.153, 21 CFR 111.155(a), 21 CFR 111.165(a), 21 CFR 111.16 | J3: same part, different section | K3: 54.49 | L3: OK | M3: FAIL | O3: Does not answer the question: lists written-procedure requirements instead of identifying 111.3 and the incorporated FD&C Act section 201 / Part 1 definitions. Cites 21 CFR 111.17, which does not exist (fabricated citation, rubric M=1). | P3: Draft key 111.3 verified correct. Cited sections (111.103, 111.135, 111.153, 111.155, 111.165, 111.16) are all unrelated to definitions. || MACHINE CHECKS: indicator: citation vs draft key: same part, different section | indicator: cited provision has no entry in the current snapshot (removed/superseded or non-existent): 21 CFR 111.17 (section_not_in_db) | pipeline validator codes on raw output: uncited_statement, material_group_uncovered | Q3: N | R3: 0 | S3: 1 | T3: 0 | U3: 0 | V3: 1 | X3: ANSWERABLE | Y3: valid | Z3: appended_missing_items | AA3: 21 CFR 111.103; 21 CFR 111.105; 21 CFR 111.10(a); 21 CFR 111.110; 21 CFR 111.113(a); 21 CFR 111.117; 21 CFR 111.120; 21 CFR 111.123(a); 21 CFR 111.127; 21 CFR 111.12(a); 21 CFR 111.130; 21 CFR 111.135; 21 CFR 111.13(a); 21 CFR 111.140(a); 21 CFR 111.14(a); 21 CFR 111.153; 21 CFR 111.155(a); 21 CFR 111.15(a); 21 CFR 111.160(a); 21 CFR 111.165(a); 21 CFR 111.16 | AC3: 21 CFR Part 111 requires written procedures for quality control operations, including material review and disposition decisions, equipment, instruments, and controls, components, packaging, and labels, master manufacturing records, batch production records, and packaging and labeling operations, personnel qualification requirements, and returned dietary supplements. The requirements under this subpart include: - Written procedures for quality control operations, as outlined in 21 CFR 111.103, 111.105, 111.10(a), 111.110, 111.113(a), 111.117, 111.120, 111.123(a), 111.127, 111.12(a), 111.130, 111.135, 111.13(a), and 111.140(a). - Personnel qualification requirements, as outlined in 21 CFR 111.140(a) and 111.14(a). - Records required under this subpart, including master manufacturing records, batch production records, and packaging and labeling operations, as outlined in 21 CFR 111.14(a). - Requirements for components, packaging, and labels before use, as outlined in 21 CFR 111.127. - Requirements for returned dietary supplements, as outlined in 21 CFR 111.135. - Requirements for product complaints, as outlined in 21 CFR 111.13(a). - Requirements for supervision of quality control operations, as outlined in 21 CFR 111.130. - Requirements for sanitation and ground maintenance, as outlined in 21 CFR 111.15(a). - Requirements for packaging and labels received, as outlined in 21 CFR 111.160(a). - Requirements for contamination and deterioration checks, as outlined in 21 CFR 111.17. | AD3: unmarked | AE3: 3
A4: S-003 | B4: Dietary Supplements — 21 CFR 111 | C4: Direct Lookup | D4: Basic | E4: What personnel qualification requirements apply under the Part 111 personnel subpart? | F4: [DRAFT KEY - NOT SME-VERIFIED] Qualified persons, education/training/experience, supervisor requirements. | G4: Under the Part 111 personnel subpart, personnel qualification requirements apply. You must have qualified employees who manufacture, package, label, or hold dietary supplements. [1] | H4: 21 CFR 111.12 | I4: Part 111, 21 CFR 111.103 | J4: same part, different section | K4: 6.75 | L4: OK | M4: FAIL | O4: States 111.12(a) correctly (qualified employees) but attributes it to source [1] = 111.103, the wrong section, and omits 111.12(b) quality-control separation of duties and (c) education/training/experience. | P4: Draft key 111.12 verified correct. Substance partly right, citation wrong and answer materially incomplete. || MACHINE CHECKS: indicator: citation vs draft key: same part, different section | pipeline validator codes on raw output: low_overlap_with_cited_source | Q4: N | R4: 0 | S4: 0 | T4: 1 | U4: 0 | V4: 1 | X4: ANSWERABLE | Y4: valid | AA4: 21 CFR 111.103; 21 CFR 111.105; 21 CFR 111.10(a); 21 CFR 111.110; 21 CFR 111.113(a); 21 CFR 111.117; 21 CFR 111.120; 21 CFR 111.123(a); 21 CFR 111.127; 21 CFR 111.12(a); 21 CFR 111.130; 21 CFR 111.135; 21 CFR 111.13(a); 21 CFR 111.140(a); 21 CFR 111.14(a); 21 CFR 111.153; 21 CFR 111.155(a); 21 CFR 111.15(a); 21 CFR 111.160(a); 21 CFR 111.165(a); 21 CFR 111.16 | AC4: Under the Part 111 personnel subpart, personnel qualification requirements apply. You must have qualified employees who manufacture, package, label, or hold dietary supplements. [1] | AD4: unmarked | AE4: 4
A5: S-004 | B5: Dietary Supplements — 21 CFR 111 | C5: Direct Lookup | D5: Basic | E5: What hygienic practices must employees follow under Part 111? | F5: [DRAFT KEY - NOT SME-VERIFIED] Handwashing, outer garments, jewelry, eating/drinking restrictions, disease control. | G5: Under Part 111, employees must establish and follow written procedures for conducting a material review and making a disposition decision, and for approving or rejecting any reprocessing. [1] Under Part 111, quality control personnel must ensure that your manufacturing, packaging, labeling, and holding operations ensure the quality of the dietary supplement and that the dietary supplement is packaged and labeled as specified in the master manufacturing record. To do so, quality control personnel must perform operations that include: [1] Under Part 111, preventing microbial contamination from sick or infected personnel and for hygienic practices must include measures to exclude any person who might be a source of microbial contamination, due to a health condition, of any material, including components, dietary supplements, and contact surfaces used in the manufacture, packaging, labeling, or holding of a dietary supplement. [3] Under Part 111, quality control operations for laboratory operations associated with the production and process control system must include: [1] Under Part 111, quality control operations for components, packaging, and labels before use in the manufacture of a dietary supplement must include: [1] Under Part 111, quality control operations for the master manufacturing record, the batch production record, and manufacturing operations must include: [1] Under Part 111, quality control operations for packaging and labeling operations must include: [1] Under Part 111, qualified employees must be assigned to supervise the manufacturing, packaging, labeling, or holding of dietary supplements. [13] Under Part 111, records required under this subpart F must be made and kept in accordance with subpart P of this part. [14] Under Part 111, records required under this subpart B must be made and kept in accordance with subpart P of this part. [15] Under Part 111, written procedures must be established and followed for fulfilling the requirements of this subpart G. [16] Under Part 111, visual examination of immediate containers or grouping of immediate containers in a shipment for appropriate content label, container damage, or broken seals must be conducted to determine whether the container condition may have resulted in contamination or deterioration of the components. [17] Under Part 111, grounds must be kept in a condition that protects against contamination of components, dietary supplements, or contact surfaces. [18] Under Part 111, packaging and labels received for packaging or labeling as a dietary supplement must be visually examined for appropriate content label, container damage, or broken seals to determine whether the container condition may have resulted in contamination or deterioration of the received product. [19] Under Part 111, the requirements for a product received for packaging or labeling as a dietary supplement (and for distribution rather than for return to the supplier) must include visual examination of immediate containers or grouping of immediate containers. [20] | H5: 21 CFR 111.13 | I5: Part 111, 21 CFR 111.103, 21 CFR 111.10(a), 21 CFR 111.13(a), 21 CFR 111.140(a), 21 CFR 111.14(a), 21 CFR 111.153, 21 CFR 111.155(a), 21 CFR 111.15(a), 21 CFR 111.160(a), 21 CFR 111.165(a) | J5: draft section cited | K5: 68.87 | L5: OK | M5: FAIL | O5: Mostly recites unrelated quality-control procedure text. One sentence on excluding sick personnel (cited to 111.10(a)) is correct, but handwashing, outer garments, jewellery and eating/drinking restrictions are all missing; the first statement cites 111.103 for a hygiene question. | P5: DRAFT KEY APPEARS INCORRECT: it names 111.13, which is supervisor requirements; hygienic practices are in 111.10. The model is not penalised for the key mismatch - it fails on substance and completeness. || MACHINE CHECKS: pipeline validator codes on raw output: uncited_statement, low_overlap_with_cited_source, repeated_statement | Q5: N | R5: 0 | S5: 0 | T5: 1 | U5: 0 | V5: 1 | X5: ANSWERABLE | Y5: valid | AA5: 21 CFR 111.103; 21 CFR 111.105; 21 CFR 111.10(a); 21 CFR 111.110; 21 CFR 111.113(a); 21 CFR 111.117; 21 CFR 111.120; 21 CFR 111.123(a); 21 CFR 111.127; 21 CFR 111.12(a); 21 CFR 111.130; 21 CFR 111.135; 21 CFR 111.13(a); 21 CFR 111.140(a); 21 CFR 111.14(a); 21 CFR 111.153; 21 CFR 111.155(a); 21 CFR 111.15(a); 21 CFR 111.160(a); 21 CFR 111.165(a); 21 CFR 111.16 | AC5: Under Part 111, employees must establish and follow written procedures for conducting a material review and making a disposition decision, and for approving or rejecting any reprocessing. [1] Under Part 111, quality control personnel must ensure that your manufacturing, packaging, labeling, and holding operations ensure the quality of the dietary supplement and that the dietary supplement is packaged and labeled as specified in the master manufacturing record. To do so, quality control personnel must perform operations that include: [1] Under Part 111, preventing microbial contamination from sick or infected personnel and for hygienic practices must include measures to exclude any person who might be a source of microbial contamination, due to a health condition, of any material, including components, dietary supplements, and contact surfaces used in the manufacture, packaging, labeling, or holding of a dietary supplement. [3] Under Part 111, quality control operations for laboratory operations associated with the production and process control system must include: [1] Under Part 111, quality control operations for components, packaging, and labels before use in the manufacture of a dietary supplement must include: [1] Under Part 111, quality control operations for the master manufacturing record, the batch production record, and manufacturing operations must include: [1] Under Part 111, quality control operations for packaging and labeling operations must include: [1] Under Part 111, qualified employees must be assigned to supervise the manufacturing, packaging, labeling, or holding of dietary supplements. [13] Under Part 111, records required under this subpart F must be made and kept in accordance with subpart P of this part. [14] Under Part 111, records required under this subpart B must be made and kept in accordance with subpart P of this part. [15] Under Part 111, written procedures must be established and followed for fulfilling the requirements of this subpart G. [16] Under Part 111, visual examination of immediate containers or grouping of immediate containers in a shipment for appropriate content label, container damage, or broken seals must be conducted to determine whether the container condition may have resulted in contamination or deterioration of the components. [17] Under Part 111, grounds must be kept in a condition that protects against contamination of components, dietary supplements, or contact surfaces. [18] Under Part 111, packaging and labels received for packaging or labeling as a dietary supplement must be visually examined for appropriate content label, container damage, or broken seals to determine whether the container condition may have resulted in contamination or deterioration of the received product. [19] Under Part 111, the requirements for a product received for packaging or labeling as a dietary supplement (and for distribution rather than for return to the supplier) must include visual examination of immediate containers or grouping of immediate containers. [20] | AD5: unmarked | AE5: 5
A6: S-005 | B6: Dietary Supplements — 21 CFR 111 | C6: Cross-Reference | D6: Intermediate | E6: What records must be made and kept under the Part 111 personnel subpart, and where are the general recordkeeping requirements for those records found? | F6: [DRAFT KEY - NOT SME-VERIFIED] Subpart B records requirement plus Subpart P general records/retention rules. | G6: Under Part 111 personnel subpart, records must be made and kept for quality control operations, including written procedures for conducting a material review and making a disposition decision, approving or rejecting any reprocessing, preventing microbial contamination from sick or infected personnel, hygienic practices, laboratory operations, and process control systems, and for components, packaging, and labels before use in the manufacture of a dietary supplement. These records must be kept in accordance with subpart P of this part [14]. | H6: 21 CFR 111.14; cross-ref 21 CFR 111.605 and 111.610 | I6: Part 111, 21 CFR 111.140(a) | J6: same part, different section | K6: 12.93 | L6: OK | M6: FAIL | O6: The subpart P cross-reference is right in substance but cited to [14] = 111.140(a) instead of 111.14/111.605. The required records (written procedures for subpart B, training documentation) are replaced by unrelated quality-control content. | P6: Draft key 111.14 + 111.605/111.610 verified correct against the snapshot. || MACHINE CHECKS: indicator: citation vs draft key: same part, different section | pipeline validator codes on raw output: uncited_statement | Q6: N | R6: 0 | S6: 0 | T6: 1 | U6: 0 | V6: 1 | X6: ANSWERABLE | Y6: valid | AA6: 21 CFR 111.103; 21 CFR 111.105; 21 CFR 111.10(a); 21 CFR 111.110; 21 CFR 111.113(a); 21 CFR 111.117; 21 CFR 111.120; 21 CFR 111.123(a); 21 CFR 111.127; 21 CFR 111.12(a); 21 CFR 111.130; 21 CFR 111.135; 21 CFR 111.13(a); 21 CFR 111.140(a); 21 CFR 111.14(a); 21 CFR 111.153; 21 CFR 111.155(a); 21 CFR 111.15(a); 21 CFR 111.160(a); 21 CFR 111.165(a); 21 CFR 111.16 | AC6: Under Part 111 personnel subpart, records must be made and kept for quality control operations, including written procedures for conducting a material review and making a disposition decision, approving or rejecting any reprocessing, preventing microbial contamination from sick or infected personnel, hygienic practices, laboratory operations, and process control systems, and for components, packaging, and labels before use in the manufacture of a dietary supplement. These records must be kept in accordance with subpart P of this part [14]. | AD6: unmarked | AE6: 6
A7: S-006 | B7: Dietary Supplements — 21 CFR 111 | C7: Direct Lookup | D7: Basic | E7: What sanitation requirements apply to the physical plant and grounds under Part 111? | F7: [DRAFT KEY - NOT SME-VERIFIED] Litter/waste, pest control, cleaning, sanitizing agents, toilet facilities, plumbing. | G7: Under Part 111, sanitation requirements apply to the physical plant and grounds, ensuring that the grounds protect against contamination of components, dietary supplements, or contact surfaces. [18] | H7: 21 CFR 111.15 | I7: Part 111, 21 CFR 111.15(a) | J7: draft section cited | K7: 7.16 | L7: OK | M7: FAIL | O7: Correctly cited (111.15(a)) and not wrong, but gives only the general purpose of ground maintenance. Litter and waste, pest control, cleaning, sanitising agents, toilet facilities and plumbing - the substance of the section - are all omitted (material omission, rubric O=0). | P7: Draft key 111.15 verified correct. Citation accuracy satisfied; fails on completeness only. || MACHINE CHECKS: no machine indicators | Q7: N | R7: 1 | S7: 0 | T7: 1 | U7: 0 | V7: 1 | X7: ANSWERABLE | Y7: valid | AA7: 21 CFR 111.103; 21 CFR 111.105; 21 CFR 111.10(a); 21 CFR 111.110; 21 CFR 111.113(a); 21 CFR 111.117; 21 CFR 111.120; 21 CFR 111.123(a); 21 CFR 111.127; 21 CFR 111.12(a); 21 CFR 111.130; 21 CFR 111.135; 21 CFR 111.13(a); 21 CFR 111.140(a); 21 CFR 111.14(a); 21 CFR 111.153; 21 CFR 111.155(a); 21 CFR 111.15(a); 21 CFR 111.160(a); 21 CFR 111.165(a); 21 CFR 111.16 | AC7: Under Part 111, sanitation requirements apply to the physical plant and grounds, ensuring that the grounds protect against contamination of components, dietary supplements, or contact surfaces. [18] | AD7: unmarked | AE7: 7
A8: S-007 | B8: Dietary Supplements — 21 CFR 111 | C8: Direct Lookup | D8: Intermediate | E8: What are the water supply requirements for a dietary supplement facility? | F8: [DRAFT KEY - NOT SME-VERIFIED] Water that contacts components/product or contact surfaces must be safe and sanitary quality. | G8: The water supply requirements for a dietary supplement facility are outlined in the FDA Guidance: Guidance for Industry: Questions and Answers Regarding Adverse Event Reporting and Recordkeeping for Dietary Supplements. A dietary supplement must be labeled as such and intended for ingestion. It must not be represented for use as a conventional food or as a sole item of a meal or the diet. Additionally, the facility must clearly identify, hold, and control under a quarantine system for appropriate disposition any dietary supplement that is rejected and unsuitable for use in manufacturing, packaging, or labeling operations. The requirements apply to devices and persons that are subject to the quarantine system [1] [4]. | H8: 21 CFR 111.16 | I8: 21 CFR 111.470 | J8: same part, different section | K8: 17.64 | L8: OK | M8: FAIL | O8: Answers with adverse-event reporting guidance and quarantine/labelling text that has nothing to do with water supply. No water requirement is stated. | P8: DRAFT KEY APPEARS INCORRECT: 111.16 is written procedures for cleaning and pest control; water supply requirements sit in 111.15. The answer is wrong against either reading. || MACHINE CHECKS: indicator: citation vs draft key: same part, different section | pipeline validator codes on raw output: invented_condition | Q8: N | R8: 0 | S8: 0 | T8: 0 | U8: 0 | V8: 1 | X8: UNKNOWN | Y8: valid | Z8: invented_conditions_removed | AA8: FDA Guidance: Guidance for Industry: Questions and Answers Regarding Adverse Event Reporting and Recordkeeping for Dietary Supplements as Required by the Dietary Supplement and Nonprescription Drug Consumer Protection Act (final, 2013-09-01, Docket FDA-2007-D-0372); 21 CFR 111.370; 21 CFR 111.155(a); 21 CFR 111.470; FDA Guidance: Guidance for Industry: Distinguishing Liquid Dietary Supplements from Beverages (final, 2014-01-14, Docket FDA-2009-D-0542) | AC8: The water supply requirements for a dietary supplement facility are outlined in the FDA Guidance: Guidance for Industry: Questions and Answers Regarding Adverse Event Reporting and Recordkeeping for Dietary Supplements. A dietary supplement must be labeled as such and intended for ingestion. It must not be represented for use as a conventional food or as a sole item of a meal or the diet. Additionally, the facility must clearly identify, hold, and control under a quarantine system for appropriate disposition any dietary supplement that is rejected and unsuitable for use in manufacturing, packaging, or labeling operations. If applicable, the requirements also apply to components of dietary supplements and to distributing dietary supplements. The requirements apply to devices and persons that are subject to the quarantine system. [1] [4] | AD8: unmarked | AE8: 8
A9: S-008 | B9: Dietary Supplements — 21 CFR 111 | C9: Direct Lookup | D9: Intermediate | E9: What design and construction requirements apply to the physical plant under Part 111? | F9: [DRAFT KEY - NOT SME-VERIFIED] Suitable size/construction/design, separation of operations, lighting, ventilation, floors/walls/ceilings. | G9: Under Part 111, the design and construction requirements apply to the physical plant and grounds, including visual examination of containers for appropriate content labels, container damage, or broken seals to determine if contamination or deterioration may have occurred. [1] The requirements for quality control personnel include ensuring the quality of dietary supplements through written procedures, including material reviews and disposition decisions, and for preventing microbial contamination from sick or infected personnel. [1] The requirements for preventing microbial contamination include excluding sources of microbial contamination from operations, and for hygienic practices. [1] The requirements for quality control operations related to laboratory operations include conducting material reviews and disposition decisions. [1] The requirements for quality control operations related to equipment, instruments, and controls include ensuring proper operation of these systems. [1] The requirements for quality control operations related to components, packaging, and labels before use include ensuring proper packaging and labeling. [1] The requirements for quality control operations related to the master manufacturing record, batch production record, and manufacturing operations include maintaining these records. [1] The requirements for quality control operations related to packaging and labeling operations include ensuring proper packaging and labeling. [1] The requirements for personnel qualification include having qualified employees who handle dietary supplements. [1] The requirements for supervisor requirements include assigning qualified personnel to supervise operations. [1] The requirements for records include making and keeping records required under this subpart F in accordance with subpart P of this part. [1] | H9: 21 CFR 111.20 | I9: Part 111, 21 CFR 111.103 | J9: same part, different section | K9: 49.03 | L9: OK | M9: FAIL | O9: Describes container inspection and quality-control operations instead of plant design and construction. None of 111.20's requirements (size, space, separation of operations, lighting, ventilation) appear; cited to 111.103. | P9: Draft key 111.20 verified correct against the snapshot. || MACHINE CHECKS: indicator: citation vs draft key: same part, different section | pipeline validator codes on raw output: low_overlap_with_cited_source | Q9: N | R9: 0 | S9: 0 | T9: 0 | U9: 0 | V9: 1 | X9: ANSWERABLE | Y9: valid | AA9: 21 CFR 111.103; 21 CFR 111.105; 21 CFR 111.10(a); 21 CFR 111.110; 21 CFR 111.113(a); 21 CFR 111.117; 21 CFR 111.120; 21 CFR 111.123(a); 21 CFR 111.127; 21 CFR 111.12(a); 21 CFR 111.130; 21 CFR 111.135; 21 CFR 111.13(a); 21 CFR 111.140(a); 21 CFR 111.14(a); 21 CFR 111.153; 21 CFR 111.155(a); 21 CFR 111.15(a); 21 CFR 111.160(a); 21 CFR 111.165(a); 21 CFR 111.16 | AC9: Under Part 111, the design and construction requirements apply to the physical plant and grounds, including visual examination of containers for appropriate content labels, container damage, or broken seals to determine if contamination or deterioration may have occurred. [1] The requirements for quality control personnel include ensuring the quality of dietary supplements through written procedures, including material reviews and disposition decisions, and for preventing microbial contamination from sick or infected personnel. [1] The requirements for preventing microbial contamination include excluding sources of microbial contamination from operations, and for hygienic practices. [1] The requirements for quality control operations related to laboratory operations include conducting material reviews and disposition decisions. [1] The requirements for quality control operations related to equipment, instruments, and controls include ensuring proper operation of these systems. [1] The requirements for quality control operations related to components, packaging, and labels before use include ensuring proper packaging and labeling. [1] The requirements for quality control operations related to the master manufacturing record, batch production record, and manufacturing operations include maintaining these records. [1] The requirements for quality control operations related to packaging and labeling operations include ensuring proper packaging and labeling. [1] The requirements for personnel qualification include having qualified employees who handle dietary supplements. [1] The requirements for supervisor requirements include assigning qualified personnel to supervise operations. [1] The requirements for records include making and keeping records required under this subpart F in accordance with subpart P of this part. [1] | AD9: unmarked | AE9: 9
A10: S-009 | B10: Dietary Supplements — 21 CFR 111 | C10: Direct Lookup | D10: Intermediate | E10: What requirements apply to automated, mechanical, or electronic equipment used in dietary supplement manufacturing? | F10: [DRAFT KEY - NOT SME-VERIFIED] Design/installation for intended use, calibration, backup, controls to prevent unauthorized changes. | G10: The requirements apply to automated, mechanical, or electronic equipment used in dietary supplement manufacturing. These include: - Design or select equipment to ensure that dietary supplement specifications are consistently met [1]. - Determine the suitability of the equipment by ensuring that your equipment is capable of operating satisfactorily within the operating limits required by the process [2]. - Establish and use appropriate controls to ensure that the equipment functions in accordance with its intended use. These controls must be approved by quality control personnel [4]. - Routinely calibrate, inspect, or check the equipment to ensure proper performance. Your quality control personnel must periodically review these calibrations, inspections, or checks [5]. - Establish and use appropriate controls for automated, mechanical, and electronic equipment (including software for a computer controlled process) to ensure that any changes to the manufacturing, packaging, labeling, holding, or other operations are approved by quality control personnel and instituted only by authorized personnel [6]. - Equipment used in automated, mechanical, or electronic systems must be identified and described [7]. | H10: 21 CFR 111.30 | I10: 21 CFR 111.30, 21 CFR 111.30(a), 21 CFR 111.30(e), 21 CFR 111.30(c), 21 CFR 111.30(d), 21 CFR 111.27(a)(1)(v) | J10: draft section cited | K10: 17.98 | L10: OK | M10: FAIL | O10: Substantively correct and complete for 111.30(a)-(e), but two citation errors: the suitability requirement (111.30(b)) is cited as 111.30(a), and a closing requirement that equipment 'must be identified and described' is attributed to 111.27(a)(1)(v), which does not state it. | P10: Draft key 111.30 verified correct. Best answer in this block; fails only on citation accuracy, which gate G1 scores at 99%. || MACHINE CHECKS: no machine indicators | Q10: N | R10: 0 | S10: 0 | T10: 2 | U10: 2 | V10: 1 | X10: UNKNOWN | Y10: valid | AA10: 21 CFR 111.30; 21 CFR 111.30(a); 21 CFR 111.30(b); 21 CFR 111.30(e); 21 CFR 111.30(c); 21 CFR 111.30(d); 21 CFR 111.27(a)(1)(v); FDA Guidance: BLA for Minimally Manipulated, Unrelated Allogeneic Placental/Umbilical Cord Blood Intended for Hematopoietic and Immunologic Reconstitution in Patients with Disorders Affecting the Hematopoietic System: Guidance for Industry (final, 2014-03-01, Docket FDA-2006-D-0157) | AC10: The requirements apply to automated, mechanical, or electronic equipment used in dietary supplement manufacturing. These include: - Design or select equipment to ensure that dietary supplement specifications are consistently met [1]. - Determine the suitability of the equipment by ensuring that your equipment is capable of operating satisfactorily within the operating limits required by the process [2]. - Establish and use appropriate controls to ensure that the equipment functions in accordance with its intended use. These controls must be approved by quality control personnel [4]. - Routinely calibrate, inspect, or check the equipment to ensure proper performance. Your quality control personnel must periodically review these calibrations, inspections, or checks [5]. - Establish and use appropriate controls for automated, mechanical, and electronic equipment (including software for a computer controlled process) to ensure that any changes to the manufacturing, packaging, labeling, holding, or other operations are approved by quality control personnel and instituted only by authorized personnel [6]. - Equipment used in automated, mechanical, or electronic systems must be identified and described [7]. | AD10: unmarked | AE10: 10
A11: S-010 | B11: Dietary Supplements — 21 CFR 111 | C11: Direct Lookup | D11: Basic | E11: What is the requirement to establish a production and process control system under Part 111? | F11: [DRAFT KEY - NOT SME-VERIFIED] Establish and follow written procedures covering all stages of manufacturing, packaging, labeling, holding. | G11: Under Part 111, you must establish and follow written procedures for the responsibilities of the quality control operations, including written procedures for conducting a material review and making a disposition decision, and for approving or rejecting any reprocessing. [1] Under Part 111, quality control personnel must ensure that your manufacturing, packaging, labeling, and holding operations ensure the quality of the dietary supplement and that the dietary supplement is packaged and labeled as specified in the master manufacturing record. To do so, quality control personnel must perform operations that include: [1] Under Part 111, you must take measures to exclude from any operations any person who might be a source of microbial contamination, due to a health condition, of any material, including components, dietary supplements, and contact surfaces used in the manufacture, packaging, labeling, or holding of a dietary supplement. [3] Under Part 111, quality control operations for laboratory operations associated with the production and process control system must include: [4] Under Part 111, quality control operations for components, packaging, and labels before use in the manufacture of a dietary supplement must include: [7] Under Part 111, quality control operations for packaging and labeling operations must include: [9] Under Part 111, quality control personnel must conduct a material review and make a disposition decision if: [5] Under Part 111, quality control personnel must establish and follow written procedures for fulfilling the requirements of this subpart G. [16] Under Part 111, you must establish and follow written procedures for cleaning the physical plant and for pest control. [16] | H11: 21 CFR 111.55 | I11: Part 111, 21 CFR 111.103, 21 CFR 111.10(a), 21 CFR 111.110, 21 CFR 111.113(a), 21 CFR 111.120, 21 CFR 111.127, 21 CFR 111.153 | J11: same part, different section | K11: 64.17 | L11: OK | M11: FAIL | O11: Never states the 111.55 requirement to implement production and process controls covering all stages. Returns quality-control procedure text cited to 111.103, 111.110, 111.113(a), 111.120 and 111.127. | P11: Draft key 111.55 verified correct against the snapshot. || MACHINE CHECKS: indicator: citation vs draft key: same part, different section | pipeline validator codes on raw output: uncited_statement, low_overlap_with_cited_source | Q11: N | R11: 0 | S11: 0 | T11: 0 | U11: 0 | V11: 1 | X11: ANSWERABLE | Y11: valid | AA11: 21 CFR 111.103; 21 CFR 111.105; 21 CFR 111.10(a); 21 CFR 111.110; 21 CFR 111.113(a); 21 CFR 111.117; 21 CFR 111.120; 21 CFR 111.123(a); 21 CFR 111.127; 21 CFR 111.12(a); 21 CFR 111.130; 21 CFR 111.135; 21 CFR 111.13(a); 21 CFR 111.140(a); 21 CFR 111.14(a); 21 CFR 111.153; 21 CFR 111.155(a); 21 CFR 111.15(a); 21 CFR 111.160(a); 21 CFR 111.165(a); 21 CFR 111.16 | AC11: Under Part 111, you must establish and follow written procedures for the responsibilities of the quality control operations, including written procedures for conducting a material review and making a disposition decision, and for approving or rejecting any reprocessing. [1] Under Part 111, quality control personnel must ensure that your manufacturing, packaging, labeling, and holding operations ensure the quality of the dietary supplement and that the dietary supplement is packaged and labeled as specified in the master manufacturing record. To do so, quality control personnel must perform operations that include: [1] Under Part 111, you must take measures to exclude from any operations any person who might be a source of microbial contamination, due to a health condition, of any material, including components, dietary supplements, and contact surfaces used in the manufacture, packaging, labeling, or holding of a dietary supplement. [3] Under Part 111, quality control operations for laboratory operations associated with the production and process control system must include: [4] Under Part 111, quality control operations for components, packaging, and labels before use in the manufacture of a dietary supplement must include: [7] Under Part 111, quality control operations for packaging and labeling operations must include: [9] Under Part 111, quality control personnel must conduct a material review and make a disposition decision if: [5] Under Part 111, quality control personnel must conduct a material review and make a disposition decision if: [11] Under Part 111, quality control personnel must conduct a material review and make a disposition decision if: [12] Under Part 111, quality control personnel must conduct a material review and make a disposition decision if: [13] Under Part 111, quality control personnel must conduct a material review and make a disposition decision if: [14] Under Part 111, quality control personnel must conduct a material review and make a disposition decision if: [15] Under Part 111, quality control personnel must conduct a material review and make a disposition decision if: [16] Under Part 111, quality control personnel must establish and follow written procedures for fulfilling the requirements of this subpart G. [16] Under Part 111, you must establish and follow written procedures for cleaning the physical plant and for pest control. [16] | AD11: unmarked | AE11: 11
A12: S-011 | B12: Dietary Supplements — 21 CFR 111 | C12: Direct Lookup | D12: Intermediate | E12: What specifications must a dietary supplement manufacturer establish? | F12: [DRAFT KEY - NOT SME-VERIFIED] Component, in-process, packaging/label, finished batch, and product-received specifications. | G12: A dietary supplement manufacturer must establish product specifications for the identity, purity, strength, and composition of the finished batch, as well as limits on contamination that may adulterate or lead to adulteration. Additionally, they must establish component specifications for each component used in the manufacture, including identity and purity, strength, and composition. These specifications must also include limits on contamination that could result in adulteration. The requirements apply to the manufacturer and their customer [1] [4]. | H12: 21 CFR 111.70 | I12: 21 CFR 111.70(e) | J12: draft section cited | K12: 13.2 | L12: OK | M12: FAIL | O12: Product and component specifications are broadly right, but in-process (111.70(c)) and packaging/label (111.70(d)) specifications are omitted, component specifications are cited to the FSVP guidance rather than Part 111, and the closing scope statement ('applies to the manufacturer and their customer') is unsupported. | P12: Draft key 111.70 verified correct. Citing an FSVP import guidance as authority for a Part 111 requirement is a citation failure. || MACHINE CHECKS: pipeline validator codes on raw output: invented_condition | Q12: N | R12: 0 | S12: 0 | T12: 1 | U12: 0 | V12: 1 | X12: UNKNOWN | Y12: valid | Z12: invented_conditions_removed | AA12: 21 CFR 111.70(e); 21 CFR 111.70(b); FDA Guidance: Draft Guidance for Industry: New Dietary Ingredient Notifications and Related Issues (draft, 2024-04-03, Docket FDA-2011-D-0376); FDA Guidance: Guidance for Industry: Foreign Supplier Verification Programs for Importers of Food for Humans and Animals (final, 2023-01-10, Docket FDA-2017-D-5225) | AC12: A dietary supplement manufacturer must establish product specifications for the identity, purity, strength, and composition of the finished batch, as well as limits on contamination that may adulterate or lead to adulteration. Additionally, they must establish component specifications for each component used in the manufacture, including identity and purity, strength, and composition. These specifications must also include limits on contamination that could result in adulteration. If applicable, the manufacturer must also include specifications for the labels and packaging that may come into contact with dietary supplements, ensuring they are safe and suitable for their intended use. The requirements apply to the manufacturer and their customer. [1][4] | AD12: unmarked | AE12: 12
A13: S-012 | B13: Dietary Supplements — 21 CFR 111 | C13: Application | D13: Advanced | E13: A finished batch fails an identity specification. What does Part 111 require the firm to do, and who makes the disposition decision? | F13: [DRAFT KEY - NOT SME-VERIFIED] Determine whether specs are met, quality control personnel material review and disposition, treatment of deviations, reprocessing limits. | G13: Part 111 requires the firm to establish and follow written procedures for conducting a material review and making a disposition decision, and for approving or rejecting any reprocessing. The disposition decision is made by the quality control personnel. [1] | H13: 21 CFR 111.73; 111.75; 111.87; 111.90 | I13: Part 111, 21 CFR 111.103 | J13: same part, different section | K13: 9.1 | L13: OK | M13: FAIL | O13: Correctly says quality-control personnel make the disposition decision, but that proposition (111.87) is cited to 111.103, and the firm's obligations under 111.73, 111.75 and 111.90 (determine whether specifications are met, reprocessing limits) are absent. | P13: Draft key 111.73/111.75/111.87/111.90 verified correct. Half the question (what the firm must do) is unanswered. || MACHINE CHECKS: indicator: citation vs draft key: same part, different section | pipeline validator codes on raw output: uncited_statement | Q13: N | R13: 0 | S13: 0 | T13: 1 | U13: 0 | V13: 1 | X13: ANSWERABLE | Y13: valid | AA13: 21 CFR 111.103; 21 CFR 111.105; 21 CFR 111.10(a); 21 CFR 111.110; 21 CFR 111.113(a); 21 CFR 111.117; 21 CFR 111.120; 21 CFR 111.123(a); 21 CFR 111.127; 21 CFR 111.12(a); 21 CFR 111.130; 21 CFR 111.135; 21 CFR 111.13(a); 21 CFR 111.140(a); 21 CFR 111.14(a); 21 CFR 111.153; 21 CFR 111.155(a); 21 CFR 111.15(a); 21 CFR 111.160(a); 21 CFR 111.165(a); 21 CFR 111.16 | AC13: Part 111 requires the firm to establish and follow written procedures for conducting a material review and making a disposition decision, and for approving or rejecting any reprocessing. The disposition decision is made by the quality control personnel. [1] | AD13: unmarked | AE13: 13
A14: S-013 | B14: Dietary Supplements — 21 CFR 111 | C14: Direct Lookup | D14: Intermediate | E14: What representative samples must be collected under Part 111, and what reserve sample requirements apply? | F14: [DRAFT KEY - NOT SME-VERIFIED] Representative samples of components, packaging, labels, in-process, finished batch; reserve sample size, storage conditions, retention period. | G14: Under Part 111, the representative samples must be collected under 21 CFR 111.103 [1], which outlines the requirements for written procedures. Quality control personnel must ensure the quality of dietary supplements through written procedures, including conducting material reviews and making disposition decisions [2]. The quality control operations required for laboratory operations associated with the production and process control system must include material reviews and disposition decisions [4]. The quality control operations for equipment, instruments, and controls must include these activities [6]. The quality control operations for components, packaging, and labels before use in the manufacture of a dietary supplement must include these activities [7]. The quality control operations for the master manufacturing record, the batch production record, and manufacturing operations must include these activities [8]. The quality control operations for packaging and labeling operations must include these activities [9]. The records required under this subpart F must be made and kept in accordance with subpart P of this part [14]. The records required under this subpart B must be made and kept in accordance with subpart P of this part [15]. The written procedures for fulfilling the requirements of this subpart G must be established and followed [16]. The requirements under this subpart G apply to components of dietary supplements [17]. The sanitation requirements apply to the physical plant and grounds [18]. The requirements under this subpart G apply to packaging and labels received [19]. The requirements under this subpart G apply to a product received for packaging or labeling as a dietary supplement [20]. The requirements under this subpart C for written procedures include cleaning the physical plant and pest control [21]. 21 CFR 111.135 (eCFR, binding, verbatim): Quality control operations for product complaints must include reviewing and approving decisions about whether to investigate a product complaint and reviewing and approving the findings and followup action of any investigation performed [12]. | H14: 21 CFR 111.80; 111.83 | I14: Part 111, 21 CFR 111.103, 21 CFR 111.135, 21 CFR 111.105, 21 CFR 111.110, 21 CFR 111.117, 21 CFR 111.120, 21 CFR 111.123(a), 21 CFR 111.127, 21 CFR 111.140(a), 21 CFR 111.14(a), 21 CFR 111.153, 21 CFR 111.155(a), 21 CFR 111.15(a), 21 CFR 111.160(a), 21 CFR 111.165(a), 21 CFR 111.16 | J14: same part, different section | K14: 63.89 | L14: OK | M14: FAIL | O14: States that representative samples are collected 'under 21 CFR 111.103', which is wrong, and never reaches 111.80 or the 111.83 reserve-sample requirements (container-closure, batch identification, retention, twice-the-quantity). | P14: Draft key 111.80/111.83 verified correct against the snapshot. || MACHINE CHECKS: indicator: citation vs draft key: same part, different section | pipeline validator codes on raw output: provision_citation_mismatch, low_overlap_with_cited_source, material_group_uncovered, repeated_statement | Q14: N | R14: 0 | S14: 0 | T14: 0 | U14: 0 | V14: 1 | X14: ANSWERABLE | Y14: incomplete | Z14: mismatched_statements_replaced+appended_missing_items | AA14: 21 CFR 111.103; 21 CFR 111.105; 21 CFR 111.10(a); 21 CFR 111.110; 21 CFR 111.113(a); 21 CFR 111.117; 21 CFR 111.120; 21 CFR 111.123(a); 21 CFR 111.127; 21 CFR 111.12(a); 21 CFR 111.130; 21 CFR 111.135; 21 CFR 111.13(a); 21 CFR 111.140(a); 21 CFR 111.14(a); 21 CFR 111.153; 21 CFR 111.155(a); 21 CFR 111.15(a); 21 CFR 111.160(a); 21 CFR 111.165(a); 21 CFR 111.16 | AC14: Under Part 111, the representative samples must be collected under 21 CFR 111.103 [1], which outlines the requirements for written procedures. Quality control personnel must ensure the quality of dietary supplements through written procedures, including conducting material reviews and making disposition decisions [2]. The reserve sample requirements apply under 21 CFR 111.105 [1], which mandates ensuring the quality of the dietary supplement through operations that include packaging and labeling. The quality control operations required for laboratory operations associated with the production and process control system must include material reviews and disposition decisions [4]. The quality control operations for equipment, instruments, and controls must include these activities [6]. The quality control operations for components, packaging, and labels before use in the manufacture of a dietary supplement must include these activities [7]. The quality control operations for the master manufacturing record, the batch production record, and manufacturing operations must include these activities [8]. The quality control operations for packaging and labeling operations must include these activities [9]. The personnel qualification requirements apply under 21 CFR 111.10(a) [10], which requires qualified employees to supervise the manufacturing, packaging, labeling, or holding of dietary supplements. The records required under this subpart F must be made and kept in accordance with subpart P of this part [14]. The records required under this subpart B must be made and kept in accordance with subpart P of this part [15]. The written procedures for fulfilling the requirements of this subpart G must be established and followed [16]. The requirements under this subpart G apply to components of dietary supplements [17]. The sanitation requirements apply to the physical plant and grounds [18]. The requirements under this subpart G apply to packaging and labels received [19]. The requirements under this subpart G apply to a product received for packaging or labeling as a dietary supplement [20]. The requirements under this subpart C for written procedures include cleaning the physical plant and pest control [21]. | AD14: unmarked | AE14: 14
